[2025-04-24T06:07:23.298+0000] {local_task_job_runner.py:123} INFO - ::group::Pre task execution logs
[2025-04-24T06:07:23.310+0000] {taskinstance.py:2614} INFO - Dependencies all met for dep_context=non-requeueable deps ti=<TaskInstance: news_etl.run_t_node manual__2025-04-24T06:07:10.814694+00:00 [queued]>
[2025-04-24T06:07:23.314+0000] {taskinstance.py:2614} INFO - Dependencies all met for dep_context=requeueable deps ti=<TaskInstance: news_etl.run_t_node manual__2025-04-24T06:07:10.814694+00:00 [queued]>
[2025-04-24T06:07:23.315+0000] {taskinstance.py:2867} INFO - Starting attempt 1 of 1
[2025-04-24T06:07:23.322+0000] {taskinstance.py:2890} INFO - Executing <Task(BashOperator): run_t_node> on 2025-04-24 06:07:10.814694+00:00
[2025-04-24T06:07:23.328+0000] {warnings.py:112} WARNING - /home/***/.local/lib/python3.12/site-packages/***/task/task_runner/standard_task_runner.py:70: DeprecationWarning: This process (pid=138) is multi-threaded, use of fork() may lead to deadlocks in the child.
  pid = os.fork()

[2025-04-24T06:07:23.329+0000] {standard_task_runner.py:104} INFO - Running: ['***', 'tasks', 'run', 'news_etl', 'run_t_node', 'manual__2025-04-24T06:07:10.814694+00:00', '--job-id', '4', '--raw', '--subdir', 'DAGS_FOLDER/New_ETL.py', '--cfg-path', '/tmp/tmpjfes914y']
[2025-04-24T06:07:23.330+0000] {standard_task_runner.py:72} INFO - Started process 189 to run task
[2025-04-24T06:07:23.330+0000] {standard_task_runner.py:105} INFO - Job 4: Subtask run_t_node
[2025-04-24T06:07:23.357+0000] {task_command.py:467} INFO - Running <TaskInstance: news_etl.run_t_node manual__2025-04-24T06:07:10.814694+00:00 [running]> on host 370799f7160e
[2025-04-24T06:07:23.398+0000] {taskinstance.py:3134} INFO - Exporting env vars: AIRFLOW_CTX_DAG_OWNER='***' AIRFLOW_CTX_DAG_ID='news_etl' AIRFLOW_CTX_TASK_ID='run_t_node' AIRFLOW_CTX_EXECUTION_DATE='2025-04-24T06:07:10.814694+00:00' AIRFLOW_CTX_TRY_NUMBER='1' AIRFLOW_CTX_DAG_RUN_ID='manual__2025-04-24T06:07:10.814694+00:00'
[2025-04-24T06:07:23.399+0000] {taskinstance.py:732} INFO - ::endgroup::
[2025-04-24T06:07:23.417+0000] {subprocess.py:78} INFO - Tmp dir root location: /tmp
[2025-04-24T06:07:23.418+0000] {subprocess.py:88} INFO - Running command: ['/usr/bin/bash', '-c', 'python /opt/***/plugins/data_collection/T_node.py']
[2025-04-24T06:07:23.426+0000] {subprocess.py:99} INFO - Output:
[2025-04-24T06:07:32.660+0000] {subprocess.py:106} INFO - 
[2025-04-24T06:07:32.661+0000] {subprocess.py:106} INFO - ✅ 저장 시작
[2025-04-24T06:07:32.661+0000] {subprocess.py:106} INFO - Traceback (most recent call last):
[2025-04-24T06:07:32.662+0000] {subprocess.py:106} INFO -   File "/opt/***/plugins/data_collection/T_node.py", line 60, in <module>
[2025-04-24T06:07:32.663+0000] {subprocess.py:106} INFO -     cursor.execute(
[2025-04-24T06:07:32.664+0000] {subprocess.py:106} INFO - psycopg2.errors.UndefinedTable: relation "keyword_freq" does not exist
[2025-04-24T06:07:32.664+0000] {subprocess.py:106} INFO - LINE 1: INSERT INTO keyword_freq (pub_date, keyword, count) VALUES (...
[2025-04-24T06:07:32.665+0000] {subprocess.py:106} INFO -                     ^
[2025-04-24T06:07:32.665+0000] {subprocess.py:106} INFO - 
[2025-04-24T06:07:32.704+0000] {subprocess.py:110} INFO - Command exited with return code 1
[2025-04-24T06:07:32.711+0000] {taskinstance.py:3313} ERROR - Task failed with exception
Traceback (most recent call last):
  File "/home/airflow/.local/lib/python3.12/site-packages/airflow/models/taskinstance.py", line 768, in _execute_task
    result = _execute_callable(context=context, **execute_callable_kwargs)
             ^^^^^^^^^^^^^^^^^^^^^^^^^^^^^^^^^^^^^^^^^^^^^^^^^^^^^^^^^^^^^
  File "/home/airflow/.local/lib/python3.12/site-packages/airflow/models/taskinstance.py", line 734, in _execute_callable
    return ExecutionCallableRunner(
           ^^^^^^^^^^^^^^^^^^^^^^^^
  File "/home/airflow/.local/lib/python3.12/site-packages/airflow/utils/operator_helpers.py", line 252, in run
    return self.func(*args, **kwargs)
           ^^^^^^^^^^^^^^^^^^^^^^^^^^
  File "/home/airflow/.local/lib/python3.12/site-packages/airflow/models/baseoperator.py", line 424, in wrapper
    return func(self, *args, **kwargs)
           ^^^^^^^^^^^^^^^^^^^^^^^^^^^
  File "/home/airflow/.local/lib/python3.12/site-packages/airflow/operators/bash.py", line 276, in execute
    raise AirflowException(
airflow.exceptions.AirflowException: Bash command failed. The command returned a non-zero exit code 1.
[2025-04-24T06:07:32.714+0000] {taskinstance.py:1226} INFO - Marking task as FAILED. dag_id=news_etl, task_id=run_t_node, run_id=manual__2025-04-24T06:07:10.814694+00:00, execution_date=20250424T060710, start_date=20250424T060723, end_date=20250424T060732
[2025-04-24T06:07:32.730+0000] {taskinstance.py:341} INFO - ::group::Post task execution logs
[2025-04-24T06:07:32.731+0000] {standard_task_runner.py:124} ERROR - Failed to execute job 4 for task run_t_node (Bash command failed. The command returned a non-zero exit code 1.; 189)
Traceback (most recent call last):
  File "/home/airflow/.local/lib/python3.12/site-packages/airflow/task/task_runner/standard_task_runner.py", line 117, in _start_by_fork
    ret = args.func(args, dag=self.dag)
          ^^^^^^^^^^^^^^^^^^^^^^^^^^^^^
  File "/home/airflow/.local/lib/python3.12/site-packages/airflow/cli/cli_config.py", line 49, in command
    return func(*args, **kwargs)
           ^^^^^^^^^^^^^^^^^^^^^
  File "/home/airflow/.local/lib/python3.12/site-packages/airflow/utils/cli.py", line 116, in wrapper
    return f(*args, **kwargs)
           ^^^^^^^^^^^^^^^^^^
  File "/home/airflow/.local/lib/python3.12/site-packages/airflow/cli/commands/task_command.py", line 483, in task_run
    task_return_code = _run_task_by_selected_method(args, _dag, ti)
                       ^^^^^^^^^^^^^^^^^^^^^^^^^^^^^^^^^^^^^^^^^^^^
  File "/home/airflow/.local/lib/python3.12/site-packages/airflow/cli/commands/task_command.py", line 256, in _run_task_by_selected_method
    return _run_raw_task(args, ti)
           ^^^^^^^^^^^^^^^^^^^^^^^
  File "/home/airflow/.local/lib/python3.12/site-packages/airflow/cli/commands/task_command.py", line 341, in _run_raw_task
    return ti._run_raw_task(
           ^^^^^^^^^^^^^^^^^
  File "/home/airflow/.local/lib/python3.12/site-packages/airflow/utils/session.py", line 97, in wrapper
    return func(*args, session=session, **kwargs)
           ^^^^^^^^^^^^^^^^^^^^^^^^^^^^^^^^^^^^^^
  File "/home/airflow/.local/lib/python3.12/site-packages/airflow/models/taskinstance.py", line 3006, in _run_raw_task
    return _run_raw_task(
           ^^^^^^^^^^^^^^
  File "/home/airflow/.local/lib/python3.12/site-packages/airflow/models/taskinstance.py", line 274, in _run_raw_task
    TaskInstance._execute_task_with_callbacks(
  File "/home/airflow/.local/lib/python3.12/site-packages/airflow/models/taskinstance.py", line 3161, in _execute_task_with_callbacks
    result = self._execute_task(context, task_orig)
             ^^^^^^^^^^^^^^^^^^^^^^^^^^^^^^^^^^^^^^
  File "/home/airflow/.local/lib/python3.12/site-packages/airflow/models/taskinstance.py", line 3185, in _execute_task
    return _execute_task(self, context, task_orig)
           ^^^^^^^^^^^^^^^^^^^^^^^^^^^^^^^^^^^^^^^
  File "/home/airflow/.local/lib/python3.12/site-packages/airflow/models/taskinstance.py", line 768, in _execute_task
    result = _execute_callable(context=context, **execute_callable_kwargs)
             ^^^^^^^^^^^^^^^^^^^^^^^^^^^^^^^^^^^^^^^^^^^^^^^^^^^^^^^^^^^^^
  File "/home/airflow/.local/lib/python3.12/site-packages/airflow/models/taskinstance.py", line 734, in _execute_callable
    return ExecutionCallableRunner(
           ^^^^^^^^^^^^^^^^^^^^^^^^
  File "/home/airflow/.local/lib/python3.12/site-packages/airflow/utils/operator_helpers.py", line 252, in run
    return self.func(*args, **kwargs)
           ^^^^^^^^^^^^^^^^^^^^^^^^^^
  File "/home/airflow/.local/lib/python3.12/site-packages/airflow/models/baseoperator.py", line 424, in wrapper
    return func(self, *args, **kwargs)
           ^^^^^^^^^^^^^^^^^^^^^^^^^^^
  File "/home/airflow/.local/lib/python3.12/site-packages/airflow/operators/bash.py", line 276, in execute
    raise AirflowException(
airflow.exceptions.AirflowException: Bash command failed. The command returned a non-zero exit code 1.
[2025-04-24T06:07:32.762+0000] {local_task_job_runner.py:266} INFO - Task exited with return code 1
[2025-04-24T06:07:32.771+0000] {taskinstance.py:3901} INFO - 0 downstream tasks scheduled from follow-on schedule check
[2025-04-24T06:07:32.772+0000] {local_task_job_runner.py:245} INFO - ::endgroup::
