[2025-04-24T05:59:27.300+0000] {local_task_job_runner.py:123} INFO - ::group::Pre task execution logs
[2025-04-24T05:59:27.310+0000] {taskinstance.py:2614} INFO - Dependencies all met for dep_context=non-requeueable deps ti=<TaskInstance: news_etl.run_e_node manual__2025-04-24T05:59:25.139019+00:00 [queued]>
[2025-04-24T05:59:27.315+0000] {taskinstance.py:2614} INFO - Dependencies all met for dep_context=requeueable deps ti=<TaskInstance: news_etl.run_e_node manual__2025-04-24T05:59:25.139019+00:00 [queued]>
[2025-04-24T05:59:27.315+0000] {taskinstance.py:2867} INFO - Starting attempt 1 of 1
[2025-04-24T05:59:27.324+0000] {taskinstance.py:2890} INFO - Executing <Task(BashOperator): run_e_node> on 2025-04-24 05:59:25.139019+00:00
[2025-04-24T05:59:27.328+0000] {warnings.py:112} WARNING - /home/***/.local/lib/python3.12/site-packages/***/task/task_runner/standard_task_runner.py:70: DeprecationWarning: This process (pid=112) is multi-threaded, use of fork() may lead to deadlocks in the child.
  pid = os.fork()

[2025-04-24T05:59:27.330+0000] {standard_task_runner.py:72} INFO - Started process 142 to run task
[2025-04-24T05:59:27.330+0000] {standard_task_runner.py:104} INFO - Running: ['***', 'tasks', 'run', 'news_etl', 'run_e_node', 'manual__2025-04-24T05:59:25.139019+00:00', '--job-id', '3', '--raw', '--subdir', 'DAGS_FOLDER/New_ETL.py', '--cfg-path', '/tmp/tmp_ofihbhl']
[2025-04-24T05:59:27.331+0000] {standard_task_runner.py:105} INFO - Job 3: Subtask run_e_node
[2025-04-24T05:59:27.359+0000] {task_command.py:467} INFO - Running <TaskInstance: news_etl.run_e_node manual__2025-04-24T05:59:25.139019+00:00 [running]> on host 2039be7d3232
[2025-04-24T05:59:27.400+0000] {taskinstance.py:3134} INFO - Exporting env vars: AIRFLOW_CTX_DAG_OWNER='***' AIRFLOW_CTX_DAG_ID='news_etl' AIRFLOW_CTX_TASK_ID='run_e_node' AIRFLOW_CTX_EXECUTION_DATE='2025-04-24T05:59:25.139019+00:00' AIRFLOW_CTX_TRY_NUMBER='1' AIRFLOW_CTX_DAG_RUN_ID='manual__2025-04-24T05:59:25.139019+00:00'
[2025-04-24T05:59:27.401+0000] {taskinstance.py:732} INFO - ::endgroup::
[2025-04-24T05:59:27.422+0000] {subprocess.py:78} INFO - Tmp dir root location: /tmp
[2025-04-24T05:59:27.423+0000] {subprocess.py:88} INFO - Running command: ['/usr/bin/bash', '-c', 'python /opt/***/plugins/data_collection/E_node.py']
[2025-04-24T05:59:27.430+0000] {subprocess.py:99} INFO - Output:
[2025-04-24T05:59:27.881+0000] {subprocess.py:106} INFO - Traceback (most recent call last):
[2025-04-24T05:59:27.882+0000] {subprocess.py:106} INFO -   File "/opt/***/plugins/data_collection/E_node.py", line 76, in <module>
[2025-04-24T05:59:27.884+0000] {subprocess.py:106} INFO -     items = get_news_list("삼성전자", 10, 1, 'date')
[2025-04-24T05:59:27.885+0000] {subprocess.py:106} INFO -             ^^^^^^^^^^^^^^^^^^^^^^^^^^^^^^^^^^^^^^^^
[2025-04-24T05:59:27.885+0000] {subprocess.py:106} INFO -   File "/opt/***/plugins/data_collection/E_node.py", line 37, in get_news_list
[2025-04-24T05:59:27.887+0000] {subprocess.py:106} INFO -     return response.json()['items']
[2025-04-24T05:59:27.887+0000] {subprocess.py:106} INFO -            ~~~~~~~~~~~~~~~^^^^^^^^^
[2025-04-24T05:59:27.887+0000] {subprocess.py:106} INFO - KeyError: 'items'
[2025-04-24T05:59:27.904+0000] {subprocess.py:110} INFO - Command exited with return code 1
[2025-04-24T05:59:27.912+0000] {taskinstance.py:3313} ERROR - Task failed with exception
Traceback (most recent call last):
  File "/home/airflow/.local/lib/python3.12/site-packages/airflow/models/taskinstance.py", line 768, in _execute_task
    result = _execute_callable(context=context, **execute_callable_kwargs)
             ^^^^^^^^^^^^^^^^^^^^^^^^^^^^^^^^^^^^^^^^^^^^^^^^^^^^^^^^^^^^^
  File "/home/airflow/.local/lib/python3.12/site-packages/airflow/models/taskinstance.py", line 734, in _execute_callable
    return ExecutionCallableRunner(
           ^^^^^^^^^^^^^^^^^^^^^^^^
  File "/home/airflow/.local/lib/python3.12/site-packages/airflow/utils/operator_helpers.py", line 252, in run
    return self.func(*args, **kwargs)
           ^^^^^^^^^^^^^^^^^^^^^^^^^^
  File "/home/airflow/.local/lib/python3.12/site-packages/airflow/models/baseoperator.py", line 424, in wrapper
    return func(self, *args, **kwargs)
           ^^^^^^^^^^^^^^^^^^^^^^^^^^^
  File "/home/airflow/.local/lib/python3.12/site-packages/airflow/operators/bash.py", line 276, in execute
    raise AirflowException(
airflow.exceptions.AirflowException: Bash command failed. The command returned a non-zero exit code 1.
[2025-04-24T05:59:27.915+0000] {taskinstance.py:1226} INFO - Marking task as FAILED. dag_id=news_etl, task_id=run_e_node, run_id=manual__2025-04-24T05:59:25.139019+00:00, execution_date=20250424T055925, start_date=20250424T055927, end_date=20250424T055927
[2025-04-24T05:59:27.931+0000] {taskinstance.py:341} INFO - ::group::Post task execution logs
[2025-04-24T05:59:27.932+0000] {standard_task_runner.py:124} ERROR - Failed to execute job 3 for task run_e_node (Bash command failed. The command returned a non-zero exit code 1.; 142)
Traceback (most recent call last):
  File "/home/airflow/.local/lib/python3.12/site-packages/airflow/task/task_runner/standard_task_runner.py", line 117, in _start_by_fork
    ret = args.func(args, dag=self.dag)
          ^^^^^^^^^^^^^^^^^^^^^^^^^^^^^
  File "/home/airflow/.local/lib/python3.12/site-packages/airflow/cli/cli_config.py", line 49, in command
    return func(*args, **kwargs)
           ^^^^^^^^^^^^^^^^^^^^^
  File "/home/airflow/.local/lib/python3.12/site-packages/airflow/utils/cli.py", line 116, in wrapper
    return f(*args, **kwargs)
           ^^^^^^^^^^^^^^^^^^
  File "/home/airflow/.local/lib/python3.12/site-packages/airflow/cli/commands/task_command.py", line 483, in task_run
    task_return_code = _run_task_by_selected_method(args, _dag, ti)
                       ^^^^^^^^^^^^^^^^^^^^^^^^^^^^^^^^^^^^^^^^^^^^
  File "/home/airflow/.local/lib/python3.12/site-packages/airflow/cli/commands/task_command.py", line 256, in _run_task_by_selected_method
    return _run_raw_task(args, ti)
           ^^^^^^^^^^^^^^^^^^^^^^^
  File "/home/airflow/.local/lib/python3.12/site-packages/airflow/cli/commands/task_command.py", line 341, in _run_raw_task
    return ti._run_raw_task(
           ^^^^^^^^^^^^^^^^^
  File "/home/airflow/.local/lib/python3.12/site-packages/airflow/utils/session.py", line 97, in wrapper
    return func(*args, session=session, **kwargs)
           ^^^^^^^^^^^^^^^^^^^^^^^^^^^^^^^^^^^^^^
  File "/home/airflow/.local/lib/python3.12/site-packages/airflow/models/taskinstance.py", line 3006, in _run_raw_task
    return _run_raw_task(
           ^^^^^^^^^^^^^^
  File "/home/airflow/.local/lib/python3.12/site-packages/airflow/models/taskinstance.py", line 274, in _run_raw_task
    TaskInstance._execute_task_with_callbacks(
  File "/home/airflow/.local/lib/python3.12/site-packages/airflow/models/taskinstance.py", line 3161, in _execute_task_with_callbacks
    result = self._execute_task(context, task_orig)
             ^^^^^^^^^^^^^^^^^^^^^^^^^^^^^^^^^^^^^^
  File "/home/airflow/.local/lib/python3.12/site-packages/airflow/models/taskinstance.py", line 3185, in _execute_task
    return _execute_task(self, context, task_orig)
           ^^^^^^^^^^^^^^^^^^^^^^^^^^^^^^^^^^^^^^^
  File "/home/airflow/.local/lib/python3.12/site-packages/airflow/models/taskinstance.py", line 768, in _execute_task
    result = _execute_callable(context=context, **execute_callable_kwargs)
             ^^^^^^^^^^^^^^^^^^^^^^^^^^^^^^^^^^^^^^^^^^^^^^^^^^^^^^^^^^^^^
  File "/home/airflow/.local/lib/python3.12/site-packages/airflow/models/taskinstance.py", line 734, in _execute_callable
    return ExecutionCallableRunner(
           ^^^^^^^^^^^^^^^^^^^^^^^^
  File "/home/airflow/.local/lib/python3.12/site-packages/airflow/utils/operator_helpers.py", line 252, in run
    return self.func(*args, **kwargs)
           ^^^^^^^^^^^^^^^^^^^^^^^^^^
  File "/home/airflow/.local/lib/python3.12/site-packages/airflow/models/baseoperator.py", line 424, in wrapper
    return func(self, *args, **kwargs)
           ^^^^^^^^^^^^^^^^^^^^^^^^^^^
  File "/home/airflow/.local/lib/python3.12/site-packages/airflow/operators/bash.py", line 276, in execute
    raise AirflowException(
airflow.exceptions.AirflowException: Bash command failed. The command returned a non-zero exit code 1.
[2025-04-24T05:59:27.945+0000] {local_task_job_runner.py:266} INFO - Task exited with return code 1
[2025-04-24T05:59:27.960+0000] {taskinstance.py:3901} INFO - 0 downstream tasks scheduled from follow-on schedule check
[2025-04-24T05:59:27.963+0000] {local_task_job_runner.py:245} INFO - ::endgroup::
